<?xml version="1.0"?>
<robot  name="collision_course" >
 <material  name="blue" >
  <color  rgba="0 0 0.8 1.0" />
 </material>
 <material  name="red" >
  <color  rgba="0.8 0 0 1.0" />
 </material>
 <material  name="white" >
  <color  rgba="1.0 1.0 1.0 0.4" />
 </material>
 <material  name="black" >
  <color  rgba="0.0 0.0 0.0 1.0" />
 </material>
 <material  name="gray" >
  <color  rgba="0.42 0.47 0.53 1.0" />
 </material>
 <link  name="root_mod" >
  <visual >
   <origin  rpy="0 0 0"  xyz="0 0 0" />
   <material  name="white" />
   <geometry >
    <cylinder  length="0.001"  radius="0.1" />
   </geometry>
  </visual>
 </link>
 <link  name="baseMod_1" >
  <inertial >
   <origin  rpy="1.5707963267948963 0.0 0.0"  xyz="0.0 1.2212453270876722e-17 0.055" />
   <mass  value="1.245" />
   <inertia  iyy="0.002417"  ixy="-0.0"  izz="0.003107"  ixz="-0.0"  iyz="1.5e-05"  ixx="0.002797" />
  </inertial>
  <visual >
   <origin  rpy="1.5707963267948963 0.0 0.0"  xyz="0.0 1.2212453270876722e-17 0.055" />
   <material  name="black" />
   <geometry >
    <mesh  filename="./meshes/base-big-360.obj"  scale="0.001 0.001 0.001" />
   </geometry>
  </visual>
  <collision >
   <origin  rpy="1.5707963267948963 0.0 0.0"  xyz="0.0 1.2212453270876722e-17 0.055" />
   <material  name="black" />
   <geometry >
    <mesh  filename="./meshes/base-big-360.obj"  scale="0.001 0.001 0.001" />
   </geometry>
  </collision>
 </link>
 <joint  type="fixed"  name="joint_1_fixed" >
  <parent  link="root_mod" />
  <child  link="baseMod_1" />
  <origin  rpy="0 0 0"  xyz="0.0 0.0 0.01" />
  <limit  upper="3.14"  velocity="10"  effort="50"  lower="-3.14" />
 </joint>
 <link  name="linkMod_2" >
  <inertial >
   <origin  rpy="0.0 -1.5707963267948966 0.0"  xyz="-1.3766765505351941e-17 0.0 -0.062" />
   <mass  value="0.167" />
   <inertia  iyy="0.000322"  ixy="0.0"  izz="0.000331"  ixz="0.0"  iyz="0.0"  ixx="2.7e-05" />
  </inertial>
  <visual >
   <origin  rpy="0.0 -1.5707963267948966 0.0"  xyz="-1.3766765505351941e-17 0.0 -0.062" />
   <material  name="blue" />
   <geometry >
    <mesh  filename="./meshes/link-150.obj"  scale="0.001 0.001 0.001" />
   </geometry>
  </visual>
  <collision >
   <origin  rpy="0.0 -1.5707963267948966 0.0"  xyz="-1.3766765505351941e-17 0.0 -0.062" />
   <material  name="blue" />
   <geometry >
    <mesh  filename="./meshes/link-150.obj"  scale="0.001 0.001 0.001" />
   </geometry>
  </collision>
 </link>
 <joint  type="revolute"  name="joint_2_revolute" >
  <parent  link="baseMod_1" />
  <child  link="linkMod_2" />
  <origin  rpy="0 0 0"  xyz="-0.0175 2.964295475749168e-17 0.1335" />
  <axis  xyz="0.0 0.0 1.0" />
  <limit  upper="3.14"  velocity="10"  effort="50"  lower="-3.14" />
 </joint>
 <transmission  name="act_joint_2_revolute" >
  <type  xmltext="SimpleTransmission" >
   SimpleTransmission
  </type>
  <actuator  name="trans_joint_2_revolute" >
   <mechanicalreduction  xmltext="1" >
    1
   </mechanicalreduction>
  </actuator>
  <joint  name="joint_2_revolute" />
 </transmission>
 <link  name="jointMod_3" >
  <inertial >
   <origin  rpy="-0.0 1.5707963267948966 0.0"  xyz="-1.1546319456101627e-17 0.0 0.052" />
   <mass  value="0.184" />
   <inertia  iyy="7.8e-05"  ixy="-1.3e-05"  izz="9e-05"  ixz="-0.0"  iyz="0.0"  ixx="7.8e-05" />
  </inertial>
  <visual >
   <origin  rpy="-0.0 1.5707963267948966 0.0"  xyz="-1.1546319456101627e-17 0.0 0.052" />
   <material  name="red" />
   <geometry >
    <mesh  filename="./meshes/90-joint.obj"  scale="0.001 0.001 0.001" />
   </geometry>
  </visual>
  <collision >
   <origin  rpy="-0.0 1.5707963267948966 0.0"  xyz="-1.1546319456101627e-17 0.0 0.052" />
   <material  name="red" />
   <geometry >
    <mesh  filename="./meshes/90-joint.obj"  scale="0.001 0.001 0.001" />
   </geometry>
  </collision>
 </link>
 <joint  type="fixed"  name="joint_3_fixed" >
  <parent  link="linkMod_2" />
  <child  link="jointMod_3" />
  <origin  rpy="0 0 0"  xyz="3.3306690738754695e-17 0.0 0.15" />
  <axis  xyz="0.0 0.0 1.0" />
  <limit  upper="3.14"  velocity="10"  effort="50"  lower="-3.14" />
 </joint>
 <link  name="linkMod_4" >
  <inertial >
   <origin  rpy="0.0 0.0 -1.5707963267948963"  xyz="-1.3766765505351941e-17 0.062 0.0" />
   <mass  value="0.05" />
   <inertia  iyy="1.3e-05"  ixy="0.0"  izz="1.6e-05"  ixz="0.0"  iyz="0.0"  ixx="8e-06" />
  </inertial>
  <visual >
   <origin  rpy="0.0 0.0 -1.5707963267948963"  xyz="-1.3766765505351941e-17 0.062 0.0" />
   <material  name="blue" />
   <geometry >
    <mesh  filename="./meshes/link-50.obj"  scale="0.001 0.001 0.001" />
   </geometry>
  </visual>
  <collision >
   <origin  rpy="0.0 0.0 -1.5707963267948963"  xyz="-1.3766765505351941e-17 0.062 0.0" />
   <material  name="blue" />
   <geometry >
    <mesh  filename="./meshes/link-50.obj"  scale="0.001 0.001 0.001" />
   </geometry>
  </collision>
 </link>
 <joint  type="revolute"  name="joint_4_revolute" >
  <parent  link="jointMod_3" />
  <child  link="linkMod_4" />
  <origin  rpy="0 0 0"  xyz="-1.1546319456101627e-17 -0.052 0.052" />
  <axis  xyz="0.0 -1.0 0.0" />
  <limit  upper="3.14"  velocity="10"  effort="50"  lower="-3.14" />
 </joint>
 <transmission  name="act_joint_4_revolute" >
  <type  xmltext="SimpleTransmission" >
   SimpleTransmission
  </type>
  <actuator  name="trans_joint_4_revolute" >
   <mechanicalreduction  xmltext="1" >
    1
   </mechanicalreduction>
  </actuator>
  <joint  name="joint_4_revolute" />
 </transmission>
 <link  name="jointMod_5" >
  <inertial >
   <origin  rpy="0.0 0.0 1.5707963267948963"  xyz="-1.1546319456101627e-17 -0.052 0.0" />
   <mass  value="0.184" />
   <inertia  iyy="7.8e-05"  ixy="-1.3e-05"  izz="9e-05"  ixz="-0.0"  iyz="0.0"  ixx="7.8e-05" />
  </inertial>
  <visual >
   <origin  rpy="0.0 0.0 1.5707963267948963"  xyz="-1.1546319456101627e-17 -0.052 0.0" />
   <material  name="red" />
   <geometry >
    <mesh  filename="./meshes/90-joint.obj"  scale="0.001 0.001 0.001" />
   </geometry>
  </visual>
  <collision >
   <origin  rpy="0.0 0.0 1.5707963267948963"  xyz="-1.1546319456101627e-17 -0.052 0.0" />
   <material  name="red" />
   <geometry >
    <mesh  filename="./meshes/90-joint.obj"  scale="0.001 0.001 0.001" />
   </geometry>
  </collision>
 </link>
 <joint  type="fixed"  name="joint_5_fixed" >
  <parent  link="linkMod_4" />
  <child  link="jointMod_5" />
  <origin  rpy="0 0 0"  xyz="1.1102230246251566e-17 -0.05 0.0" />
  <axis  xyz="0.0 -1.0 0.0" />
  <limit  upper="3.14"  velocity="10"  effort="50"  lower="-3.14" />
 </joint>
 <link  name="linkMod_6" >
  <inertial >
   <origin  rpy="0.0 0.0 0.0"  xyz="-0.062 0.0 0.0" />
   <mass  value="0.05" />
   <inertia  iyy="1.3e-05"  ixy="0.0"  izz="1.6e-05"  ixz="0.0"  iyz="0.0"  ixx="8e-06" />
  </inertial>
  <visual >
   <origin  rpy="0.0 0.0 0.0"  xyz="-0.062 0.0 0.0" />
   <material  name="blue" />
   <geometry >
    <mesh  filename="./meshes/link-50.obj"  scale="0.001 0.001 0.001" />
   </geometry>
  </visual>
  <collision >
   <origin  rpy="0.0 0.0 0.0"  xyz="-0.062 0.0 0.0" />
   <material  name="blue" />
   <geometry >
    <mesh  filename="./meshes/link-50.obj"  scale="0.001 0.001 0.001" />
   </geometry>
  </collision>
 </link>
 <joint  type="revolute"  name="joint_6_revolute" >
  <parent  link="jointMod_5" />
  <child  link="linkMod_6" />
  <origin  rpy="0 0 0"  xyz="0.051999999999999984 -0.05200000000000001 0.0" />
  <axis  xyz="1.0 -0.0 0.0" />
  <limit  upper="3.14"  velocity="10"  effort="50"  lower="-3.14" />
 </joint>
 <transmission  name="act_joint_6_revolute" >
  <type  xmltext="SimpleTransmission" >
   SimpleTransmission
  </type>
  <actuator  name="trans_joint_6_revolute" >
   <mechanicalreduction  xmltext="1" >
    1
   </mechanicalreduction>
  </actuator>
  <joint  name="joint_6_revolute" />
 </transmission>
 <link  name="connMod_7" >
  <inertial >
   <origin  rpy="0.0 0.0 -1.5707963267948963"  xyz="0.02 4.440892098500626e-18 0.0" />
   <mass  value="0.263" />
   <inertia  iyy="0.00023"  ixy="0.0"  izz="0.000125"  ixz="-0.0"  iyz="-1.5e-05"  ixx="0.000226" />
  </inertial>
  <visual >
   <origin  rpy="0.0 0.0 -1.5707963267948963"  xyz="0.02 4.440892098500626e-18 0.0" />
   <material  name="white" />
   <geometry >
    <mesh  filename="./meshes/90-connector.obj"  scale="0.001 0.001 0.001" />
   </geometry>
  </visual>
  <collision >
   <origin  rpy="0.0 0.0 -1.5707963267948963"  xyz="0.02 4.440892098500626e-18 0.0" />
   <material  name="white" />
   <geometry >
    <mesh  filename="./meshes/90-connector.obj"  scale="0.001 0.001 0.001" />
   </geometry>
  </collision>
 </link>
 <joint  type="fixed"  name="joint_7_fixed" >
  <parent  link="linkMod_6" />
  <child  link="connMod_7" />
  <origin  rpy="0 0 0"  xyz="0.05 0.0 0.0" />
  <axis  xyz="1.0 0.0 0.0" />
  <limit  upper="3.14"  velocity="10"  effort="50"  lower="-3.14" />
 </joint>
 <link  name="linkMod_8" >
  <inertial >
   <origin  rpy="0.0 -1.5707963267948966 0.0"  xyz="-1.3766765505351941e-17 0.0 -0.062" />
   <mass  value="0.167" />
   <inertia  iyy="0.000322"  ixy="0.0"  izz="0.000331"  ixz="0.0"  iyz="0.0"  ixx="2.7e-05" />
  </inertial>
  <visual >
   <origin  rpy="0.0 -1.5707963267948966 0.0"  xyz="-1.3766765505351941e-17 0.0 -0.062" />
   <material  name="blue" />
   <geometry >
    <mesh  filename="./meshes/link-150.obj"  scale="0.001 0.001 0.001" />
   </geometry>
  </visual>
  <collision >
   <origin  rpy="0.0 -1.5707963267948966 0.0"  xyz="-1.3766765505351941e-17 0.0 -0.062" />
   <material  name="blue" />
   <geometry >
    <mesh  filename="./meshes/link-150.obj"  scale="0.001 0.001 0.001" />
   </geometry>
  </collision>
 </link>
 <joint  type="fixed"  name="joint_8_fixed" >
  <parent  link="connMod_7" />
  <child  link="linkMod_8" />
  <origin  rpy="0 0 0"  xyz="0.02 4.440892098500626e-18 0.06" />
  <axis  xyz="0.0 0.0 1.0" />
  <limit  upper="3.14"  velocity="10"  effort="50"  lower="-3.14" />
 </joint>
 <link  name="eefMod_9" >
  <inertial >
   <origin  rpy="0.0 -1.5707963267948966 0.0"  xyz="6.439293542825908e-18 0.0 0.029" />
   <mass  value="0.5" />
   <inertia  iyy="0"  ixy="0"  izz="0"  ixz="0"  iyz="0"  ixx="0" />
  </inertial>
  <visual >
   <origin  rpy="0.0 -1.5707963267948966 0.0"  xyz="6.439293542825908e-18 0.0 0.029" />
   <material  name="gray" />
   <geometry >
    <mesh  filename="./meshes/eef1l.obj"  scale="0.001 0.001 0.001" />
   </geometry>
  </visual>
  <collision >
   <origin  rpy="0.0 -1.5707963267948966 0.0"  xyz="6.439293542825908e-18 0.0 0.029" />
   <material  name="gray" />
   <geometry >
    <mesh  filename="./meshes/eef1l.obj"  scale="0.001 0.001 0.001" />
   </geometry>
  </collision>
 </link>
 <joint  type="fixed"  name="joint_9_fixed" >
  <parent  link="linkMod_8" />
  <child  link="eefMod_9" />
  <origin  rpy="0 0 0"  xyz="3.3306690738754695e-17 0.0 0.15" />
  <axis  xyz="0.0 0.0 1.0" />
  <limit  upper="3.14"  velocity="10"  effort="50"  lower="-3.14" />
 </joint>
 <link  name="eef" >
  <inertial >
   <mass  value="0" />
  </inertial>
 </link>
 <joint  type="fixed"  name="eef_joint" >
  <parent  link="eefMod_9" />
  <child  link="eef" />
  <origin  rpy="0.0 -1.5707963267948966 0.0"  xyz="-0.009999999999999976 0.0 0.109" />
  <limit  upper="3.14"  velocity="10"  effort="50"  lower="-3.14" />
 </joint>
</robot>

