<?xml version="1.0"?>
<robot  name="test" >
 <material  name="blue" >
  <color  rgba="0 0 0.8 1.0" />
 </material>
 <material  name="red" >
  <color  rgba="0.8 0 0 1.0" />
 </material>
 <material  name="white" >
  <color  rgba="1.0 1.0 1.0 0.4" />
 </material>
 <material  name="black" >
  <color  rgba="0.0 0.0 0.0 1.0" />
 </material>
 <link  name="root_mod" >
  <visual >
   <origin  rpy="0 0 0"  xyz="0 0 0" />
   <material  name="white" />
   <geometry >
    <cylinder  radius="0.1"  length="0.001" />
   </geometry>
  </visual>
 </link>
 <link  name="connMod_1" >
  <inertial >
   <origin  rpy="1.5707963267948963 0.0 0.0"  xyz="0.0 1.2212453270876722e-17 0.055" />
   <mass  value="1.245" />
   <inertia  iyz="1.5e-05"  ixy="-0.0"  izz="0.003107"  ixz="-0.0"  iyy="0.002417"  ixx="0.002797" />
  </inertial>
  <visual >
   <origin  rpy="1.5707963267948963 0.0 0.0"  xyz="0.0 1.2212453270876722e-17 0.055" />
   <material  name="black" />
   <geometry >
    <mesh  filename="./meshes/base-big-360.obj"  scale="0.001 0.001 0.001" />
   </geometry>
  </visual>
 </link>
 <joint  name="joint_1_fixed"  type="fixed" >
  <parent  link="root_mod" />
  <child  link="connMod_1" />
  <origin  rpy="0 0 0"  xyz="0.0 0.0 0.01" />
  <limit  lower="-3.14"  velocity="10"  effort="50"  upper="3.14" />
 </joint>
 <link  name="connMod_2" >
  <inertial >
   <origin  rpy="-0.0 1.5707963267948966 0.0"  xyz="-1.3766765505351941e-17 0.0 0.062" />
   <mass  value="0.032" />
   <inertia  iyz="0.0"  ixy="0.0"  izz="1.2e-05"  ixz="0.0"  iyy="1.1e-05"  ixx="2.1e-05" />
  </inertial>
  <visual >
   <origin  rpy="-0.0 1.5707963267948966 0.0"  xyz="-1.3766765505351941e-17 0.0 0.062" />
   <material  name="white" />
   <geometry >
    <mesh  filename="./meshes/connector-0.obj"  scale="0.001 0.001 0.001" />
   </geometry>
  </visual>
 </link>
 <joint  name="joint_2_revolute"  type="revolute" >
  <parent  link="connMod_1" />
  <child  link="connMod_2" />
  <origin  rpy="0 0 0"  xyz="-0.0175 2.964295475749168e-17 0.1335" />
  <axis  xyz="0.0 0.0 1.0" />
  <limit  lower="-3.14"  velocity="10"  effort="50"  upper="3.14" />
 </joint>
 <transmission  name="act_joint_2_revolute" >
  <type  xmltext="SimpleTransmission" >
   SimpleTransmission
  </type>
  <actuator  name="trans_joint_2_revolute" >
   <mechanicalreduction  xmltext="1" >
    1
   </mechanicalreduction>
  </actuator>
  <joint  name="joint_2_revolute" />
 </transmission>
 <link  name="linkMod_3" >
  <inertial >
   <origin  rpy="0.0 -1.5707963267948966 0.0"  xyz="-1.3766765505351941e-17 0.0 -0.062" />
   <mass  value="0.167" />
   <inertia  iyz="0.0"  ixy="0.0"  izz="0.000331"  ixz="0.0"  iyy="0.000322"  ixx="2.7e-05" />
  </inertial>
  <visual >
   <origin  rpy="0.0 -1.5707963267948966 0.0"  xyz="-1.3766765505351941e-17 0.0 -0.062" />
   <material  name="blue" />
   <geometry >
    <mesh  filename="./meshes/link-150.obj"  scale="0.001 0.001 0.001" />
   </geometry>
  </visual>
 </link>
 <joint  name="joint_3_revolute"  type="revolute" >
  <parent  link="connMod_2" />
  <child  link="linkMod_3" />
  <origin  rpy="0 0 0"  xyz="-4.44089209850063e-19 0.0 0.0020000000000000018" />
  <axis  xyz="-0.0 0.0 1.0" />
  <limit  lower="-3.14"  velocity="10"  effort="50"  upper="3.14" />
 </joint>
 <transmission  name="act_joint_3_revolute" >
  <type  xmltext="SimpleTransmission" >
   SimpleTransmission
  </type>
  <actuator  name="trans_joint_3_revolute" >
   <mechanicalreduction  xmltext="1" >
    1
   </mechanicalreduction>
  </actuator>
  <joint  name="joint_3_revolute" />
 </transmission>
 <link  name="connMod_4" >
  <inertial >
   <origin  rpy="-0.0 1.5707963267948966 0.0"  xyz="-1.3766765505351941e-17 0.0 0.062" />
   <mass  value="0.032" />
   <inertia  iyz="0.0"  ixy="0.0"  izz="1.2e-05"  ixz="0.0"  iyy="1.1e-05"  ixx="2.1e-05" />
  </inertial>
  <visual >
   <origin  rpy="-0.0 1.5707963267948966 0.0"  xyz="-1.3766765505351941e-17 0.0 0.062" />
   <material  name="white" />
   <geometry >
    <mesh  filename="./meshes/connector-0.obj"  scale="0.001 0.001 0.001" />
   </geometry>
  </visual>
 </link>
 <joint  name="joint_4_revolute"  type="revolute" >
  <parent  link="linkMod_3" />
  <child  link="connMod_4" />
  <origin  rpy="0 0 0"  xyz="3.3306690738754695e-17 0.0 0.15" />
  <axis  xyz="0.0 0.0 1.0" />
  <limit  lower="-3.14"  velocity="10"  effort="50"  upper="3.14" />
 </joint>
 <transmission  name="act_joint_4_revolute" >
  <type  xmltext="SimpleTransmission" >
   SimpleTransmission
  </type>
  <actuator  name="trans_joint_4_revolute" >
   <mechanicalreduction  xmltext="1" >
    1
   </mechanicalreduction>
  </actuator>
  <joint  name="joint_4_revolute" />
 </transmission>
 <link  name="jointMod_5" >
  <inertial >
   <origin  rpy="-0.0 1.5707963267948966 0.0"  xyz="-1.1546319456101627e-17 0.0 0.052" />
   <mass  value="0.184" />
   <inertia  iyz="0.0"  ixy="-1.3e-05"  izz="9e-05"  ixz="-0.0"  iyy="7.8e-05"  ixx="7.8e-05" />
  </inertial>
  <visual >
   <origin  rpy="-0.0 1.5707963267948966 0.0"  xyz="-1.1546319456101627e-17 0.0 0.052" />
   <material  name="red" />
   <geometry >
    <mesh  filename="./meshes/90-joint.obj"  scale="0.001 0.001 0.001" />
   </geometry>
  </visual>
 </link>
 <joint  name="joint_5_fixed"  type="fixed" >
  <parent  link="connMod_4" />
  <child  link="jointMod_5" />
  <origin  rpy="0 0 0"  xyz="-4.44089209850063e-19 0.0 0.0020000000000000018" />
  <axis  xyz="-0.0 0.0 1.0" />
  <limit  lower="-3.14"  velocity="10"  effort="50"  upper="3.14" />
 </joint>
 <link  name="linkMod_6" >
  <inertial >
   <origin  rpy="0.0 0.0 -1.5707963267948963"  xyz="-1.3766765505351941e-17 0.062 0.0" />
   <mass  value="0.05" />
   <inertia  iyz="0.0"  ixy="0.0"  izz="0.000206"  ixz="0.0"  iyy="0.000206"  ixx="6.5e-05" />
  </inertial>
  <visual >
   <origin  rpy="0.0 0.0 -1.5707963267948963"  xyz="-1.3766765505351941e-17 0.062 0.0" />
   <material  name="blue" />
   <geometry >
    <mesh  filename="./meshes/link-100.obj"  scale="0.001 0.001 0.001" />
   </geometry>
  </visual>
 </link>
 <joint  name="joint_6_revolute"  type="revolute" >
  <parent  link="jointMod_5" />
  <child  link="linkMod_6" />
  <origin  rpy="0 0 0"  xyz="-1.1546319456101627e-17 -0.052 0.052" />
  <axis  xyz="0.0 -1.0 0.0" />
  <limit  lower="-3.14"  velocity="10"  effort="50"  upper="3.14" />
 </joint>
 <transmission  name="act_joint_6_revolute" >
  <type  xmltext="SimpleTransmission" >
   SimpleTransmission
  </type>
  <actuator  name="trans_joint_6_revolute" >
   <mechanicalreduction  xmltext="1" >
    1
   </mechanicalreduction>
  </actuator>
  <joint  name="joint_6_revolute" />
 </transmission>
 <link  name="connMod_7" >
  <inertial >
   <origin  rpy="-1.5707963267948963 0.0 0.0"  xyz="0.0 -0.02500000000000001 0.034999999999999996" />
   <mass  value="0.423" />
   <inertia  iyz="3e-06"  ixy="0.0"  izz="0.000522"  ixz="0.0"  iyy="0.000198"  ixx="0.000524" />
  </inertial>
  <visual >
   <origin  rpy="-1.5707963267948963 0.0 0.0"  xyz="0.0 -0.02500000000000001 0.034999999999999996" />
   <material  name="white" />
   <geometry >
    <mesh  filename="./meshes/180-connector-2.obj"  scale="0.001 0.001 0.001" />
   </geometry>
  </visual>
 </link>
 <joint  name="joint_7_revolute"  type="revolute" >
  <parent  link="linkMod_6" />
  <child  link="connMod_7" />
  <origin  rpy="0 0 0"  xyz="2.2204460492503132e-17 -0.1 0.0" />
  <axis  xyz="0.0 -1.0 0.0" />
  <limit  lower="-3.14"  velocity="10"  effort="50"  upper="3.14" />
 </joint>
 <transmission  name="act_joint_7_revolute" >
  <type  xmltext="SimpleTransmission" >
   SimpleTransmission
  </type>
  <actuator  name="trans_joint_7_revolute" >
   <mechanicalreduction  xmltext="1" >
    1
   </mechanicalreduction>
  </actuator>
  <joint  name="joint_7_revolute" />
 </transmission>
 <link  name="jointMod_8" >
  <inertial >
   <origin  rpy="0.0 0.0 -1.5707963267948963"  xyz="-1.1546319456101627e-17 0.052 0.0" />
   <mass  value="0.184" />
   <inertia  iyz="0.0"  ixy="-1.3e-05"  izz="9e-05"  ixz="-0.0"  iyy="7.8e-05"  ixx="7.8e-05" />
  </inertial>
  <visual >
   <origin  rpy="0.0 0.0 -1.5707963267948963"  xyz="-1.1546319456101627e-17 0.052 0.0" />
   <material  name="red" />
   <geometry >
    <mesh  filename="./meshes/90-joint.obj"  scale="0.001 0.001 0.001" />
   </geometry>
  </visual>
 </link>
 <joint  name="joint_8_fixed"  type="fixed" >
  <parent  link="connMod_7" />
  <child  link="jointMod_8" />
  <origin  rpy="0 0 0"  xyz="0.0 -1.3877787807814457e-17 0.07" />
  <axis  xyz="0.0 1.0 0.0" />
  <limit  lower="-3.14"  velocity="10"  effort="50"  upper="3.14" />
 </joint>
 <link  name="connMod_9" >
  <inertial >
   <origin  rpy="0.0 0.0 0.0"  xyz="-0.062 0.0 0.0" />
   <mass  value="0.032" />
   <inertia  iyz="0.0"  ixy="0.0"  izz="1.2e-05"  ixz="0.0"  iyy="1.1e-05"  ixx="2.1e-05" />
  </inertial>
  <visual >
   <origin  rpy="0.0 0.0 0.0"  xyz="-0.062 0.0 0.0" />
   <material  name="white" />
   <geometry >
    <mesh  filename="./meshes/connector-0.obj"  scale="0.001 0.001 0.001" />
   </geometry>
  </visual>
 </link>
 <joint  name="joint_9_revolute"  type="revolute" >
  <parent  link="jointMod_8" />
  <child  link="connMod_9" />
  <origin  rpy="0 0 0"  xyz="-0.05200000000000001 0.051999999999999984 0.0" />
  <axis  xyz="-1.0 -0.0 0.0" />
  <limit  lower="-3.14"  velocity="10"  effort="50"  upper="3.14" />
 </joint>
 <transmission  name="act_joint_9_revolute" >
  <type  xmltext="SimpleTransmission" >
   SimpleTransmission
  </type>
  <actuator  name="trans_joint_9_revolute" >
   <mechanicalreduction  xmltext="1" >
    1
   </mechanicalreduction>
  </actuator>
  <joint  name="joint_9_revolute" />
 </transmission>
 <link  name="linkMod_10" >
  <inertial >
   <origin  rpy="1.5707963240855651 -1.2497703982816688e-08 -3.141592641092089"  xyz="0.06199999999999997 7.748576576602542e-10 -7.74857655560908e-10" />
   <mass  value="0.05" />
   <inertia  iyz="0.0"  ixy="0.0"  izz="1.6e-05"  ixz="0.0"  iyy="1.3e-05"  ixx="8e-06" />
  </inertial>
  <visual >
   <origin  rpy="1.5707963240855651 -1.2497703982816688e-08 -3.141592641092089"  xyz="0.06199999999999997 7.748576576602542e-10 -7.74857655560908e-10" />
   <material  name="blue" />
   <geometry >
    <mesh  filename="./meshes/link-50.obj"  scale="0.001 0.001 0.001" />
   </geometry>
  </visual>
 </link>
 <joint  name="joint_10_revolute"  type="revolute" >
  <parent  link="connMod_9" />
  <child  link="linkMod_10" />
  <origin  rpy="0 0 0"  xyz="-0.0020000000000000018 0.0 0.0" />
  <axis  xyz="-1.0 0.0 0.0" />
  <limit  lower="-3.14"  velocity="10"  effort="50"  upper="3.14" />
 </joint>
 <transmission  name="act_joint_10_revolute" >
  <type  xmltext="SimpleTransmission" >
   SimpleTransmission
  </type>
  <actuator  name="trans_joint_10_revolute" >
   <mechanicalreduction  xmltext="1" >
    1
   </mechanicalreduction>
  </actuator>
  <joint  name="joint_10_revolute" />
 </transmission>
</robot>
