<?xml version="1.0"?>
<robot  name="node12" >
 <material  name="blue" >
  <color  rgba="0 0 0.8 1.0" />
 </material>
 <material  name="red" >
  <color  rgba="0.8 0 0 1.0" />
 </material>
 <material  name="white" >
  <color  rgba="1.0 1.0 1.0 0.4" />
 </material>
 <material  name="black" >
  <color  rgba="0.0 0.0 0.0 1.0" />
 </material>
 <link  name="root_mod" >
  <visual >
   <origin  xyz="0 0 0"  rpy="0 0 0" />
   <material  name="white" />
   <geometry >
    <cylinder  length="0.001"  radius="0.1" />
   </geometry>
  </visual>
 </link>
 <link  name="baseMod_1" >
  <inertial >
   <origin  xyz="0.0 1.2212453270876722e-17 0.055"  rpy="1.5707963267948963 0.0 0.0" />
   <mass  value="1.245" />
   <inertia  iyz="1.5e-05"  ixx="0.002797"  ixz="-0.0"  ixy="-0.0"  izz="0.003107"  iyy="0.002417" />
  </inertial>
  <visual >
   <origin  xyz="0.0 1.2212453270876722e-17 0.055"  rpy="1.5707963267948963 0.0 0.0" />
   <material  name="black" />
   <geometry >
    <mesh  filename="./meshes/base-big-360.obj"  scale="0.001 0.001 0.001" />
   </geometry>
  </visual>
 </link>
 <joint  name="joint_1_fixed"  type="fixed" >
  <parent  link="root_mod" />
  <child  link="baseMod_1" />
  <origin  xyz="0.0 0.0 0.01"  rpy="0 0 0" />
  <limit  effort="50"  upper="3.14"  velocity="10"  lower="-3.14" />
 </joint>
 <link  name="connMod_2" >
  <inertial >
   <origin  xyz="0.0 4.440892098500626e-18 0.02"  rpy="1.5707963267948963 0.0 0.0" />
   <mass  value="0.263" />
   <inertia  iyz="-1.5e-05"  ixx="0.000226"  ixz="-0.0"  ixy="0.0"  izz="0.000125"  iyy="0.00023" />
  </inertial>
  <visual >
   <origin  xyz="0.0 4.440892098500626e-18 0.02"  rpy="1.5707963267948963 0.0 0.0" />
   <material  name="white" />
   <geometry >
    <mesh  filename="./meshes/90-connector.obj"  scale="0.001 0.001 0.001" />
   </geometry>
  </visual>
 </link>
 <joint  name="joint_2_revolute"  type="revolute" >
  <parent  link="baseMod_1" />
  <child  link="connMod_2" />
  <origin  xyz="-0.0175 2.964295475749168e-17 0.1335"  rpy="0 0 0" />
  <axis  xyz="0.0 0.0 1.0" />
  <limit  velocity="10"  upper="3.14"  effort="50"  lower="-3.14" />
 </joint>
 <transmission  name="act_joint_2_revolute" >
  <type  xmltext="SimpleTransmission" >
   SimpleTransmission
  </type>
  <actuator  name="trans_joint_2_revolute" >
   <mechanicalreduction  xmltext="1" >
    1
   </mechanicalreduction>
  </actuator>
  <joint  name="joint_2_revolute" />
 </transmission>
 <link  name="linkMod_3" >
  <inertial >
   <origin  xyz="-1.3766765505351941e-17 0.062 0.0"  rpy="0.0 0.0 -1.5707963267948963" />
   <mass  value="0.167" />
   <inertia  iyz="0.0"  ixx="2.7e-05"  ixz="0.0"  ixy="0.0"  izz="0.000331"  iyy="0.000322" />
  </inertial>
  <visual >
   <origin  xyz="-1.3766765505351941e-17 0.062 0.0"  rpy="0.0 0.0 -1.5707963267948963" />
   <material  name="blue" />
   <geometry >
    <mesh  filename="./meshes/link-150.obj"  scale="0.001 0.001 0.001" />
   </geometry>
  </visual>
 </link>
 <joint  name="joint_3_fixed"  type="fixed" >
  <parent  link="connMod_2" />
  <child  link="linkMod_3" />
  <origin  xyz="0.0 -0.05999999999999999 0.020000000000000014"  rpy="0 0 0" />
  <axis  xyz="0.0 -1.0 0.0" />
  <limit  effort="50"  upper="3.14"  velocity="10"  lower="-3.14" />
 </joint>
 <link  name="eef" />
 <joint  name="eef_joint"  type="fixed" >
  <parent  link="linkMod_3" />
  <child  link="eef" />
  <origin  xyz="3.3306690738754695e-17 -0.15 0.0"  rpy="0 0 0" />
  <axis  xyz="0.0 -1.0 0.0" />
  <limit  velocity="10"  upper="3.14"  effort="50"  lower="-3.14" />
 </joint>
</robot>

